[2022-01-05 08:52:24,734] {taskinstance.py:851} INFO - Dependencies all met for <TaskInstance: generate_data.generate_data 2022-01-04T00:00:00+00:00 [queued]>
[2022-01-05 08:52:25,152] {taskinstance.py:851} INFO - Dependencies all met for <TaskInstance: generate_data.generate_data 2022-01-04T00:00:00+00:00 [queued]>
[2022-01-05 08:52:25,152] {taskinstance.py:1042} INFO - 
--------------------------------------------------------------------------------
[2022-01-05 08:52:25,154] {taskinstance.py:1043} INFO - Starting attempt 1 of 1
[2022-01-05 08:52:25,154] {taskinstance.py:1044} INFO - 
--------------------------------------------------------------------------------
[2022-01-05 08:52:25,409] {taskinstance.py:1063} INFO - Executing <Task(PythonOperator): generate_data> on 2022-01-04T00:00:00+00:00
[2022-01-05 08:52:25,535] {standard_task_runner.py:52} INFO - Started process 59 to run task
[2022-01-05 08:52:25,670] {standard_task_runner.py:76} INFO - Running: ['airflow', 'tasks', 'run', 'generate_data', 'generate_data', '2022-01-04T00:00:00+00:00', '--job-id', '2', '--pool', 'default_pool', '--raw', '--subdir', 'DAGS_FOLDER/sqldata.py', '--cfg-path', '/tmp/tmpvnfi13uc', '--error-file', '/tmp/tmp9_26gkgq']
[2022-01-05 08:52:25,671] {standard_task_runner.py:77} INFO - Job 2: Subtask generate_data
[2022-01-05 08:52:25,963] {logging_mixin.py:104} INFO - Running <TaskInstance: generate_data.generate_data 2022-01-04T00:00:00+00:00 [running]> on host e72c695c336a
[2022-01-05 08:52:26,351] {taskinstance.py:1257} INFO - Exporting the following env vars:
AIRFLOW_CTX_DAG_OWNER=airflow
AIRFLOW_CTX_DAG_ID=generate_data
AIRFLOW_CTX_TASK_ID=generate_data
AIRFLOW_CTX_EXECUTION_DATE=2022-01-04T00:00:00+00:00
AIRFLOW_CTX_DAG_RUN_ID=scheduled__2022-01-04T00:00:00+00:00
[2022-01-05 08:52:28,689] {taskinstance.py:1455} ERROR - [Errno 2] No such file or directory: './data/raw_cdr_data.csv'
Traceback (most recent call last):
  File "/home/airflow/.local/lib/python3.6/site-packages/airflow/models/taskinstance.py", line 1112, in _run_raw_task
    self._prepare_and_execute_task_with_callbacks(context, task)
  File "/home/airflow/.local/lib/python3.6/site-packages/airflow/models/taskinstance.py", line 1285, in _prepare_and_execute_task_with_callbacks
    result = self._execute_task(context, task_copy)
  File "/home/airflow/.local/lib/python3.6/site-packages/airflow/models/taskinstance.py", line 1315, in _execute_task
    result = task_copy.execute(context=context)
  File "/home/airflow/.local/lib/python3.6/site-packages/airflow/operators/python.py", line 117, in execute
    return_value = self.execute_callable()
  File "/home/airflow/.local/lib/python3.6/site-packages/airflow/operators/python.py", line 128, in execute_callable
    return self.python_callable(*self.op_args, **self.op_kwargs)
  File "/opt/airflow/dags/sqldata.py", line 20, in generate_data
    raw_cdr_data = pd.read_csv(dataset_name, header=None, low_memory=False)
  File "/home/airflow/.local/lib/python3.6/site-packages/pandas/io/parsers.py", line 688, in read_csv
    return _read(filepath_or_buffer, kwds)
  File "/home/airflow/.local/lib/python3.6/site-packages/pandas/io/parsers.py", line 454, in _read
    parser = TextFileReader(fp_or_buf, **kwds)
  File "/home/airflow/.local/lib/python3.6/site-packages/pandas/io/parsers.py", line 948, in __init__
    self._make_engine(self.engine)
  File "/home/airflow/.local/lib/python3.6/site-packages/pandas/io/parsers.py", line 1180, in _make_engine
    self._engine = CParserWrapper(self.f, **self.options)
  File "/home/airflow/.local/lib/python3.6/site-packages/pandas/io/parsers.py", line 2010, in __init__
    self._reader = parsers.TextReader(src, **kwds)
  File "pandas/_libs/parsers.pyx", line 382, in pandas._libs.parsers.TextReader.__cinit__
  File "pandas/_libs/parsers.pyx", line 674, in pandas._libs.parsers.TextReader._setup_parser_source
FileNotFoundError: [Errno 2] No such file or directory: './data/raw_cdr_data.csv'
[2022-01-05 08:52:29,596] {taskinstance.py:1503} INFO - Marking task as FAILED. dag_id=generate_data, task_id=generate_data, execution_date=20220104T000000, start_date=20220105T085224, end_date=20220105T085229
[2022-01-05 08:52:29,945] {local_task_job.py:146} INFO - Task exited with return code 1
[2022-01-05 12:17:42,607] {taskinstance.py:851} INFO - Dependencies all met for <TaskInstance: generate_data.generate_data 2022-01-04T00:00:00+00:00 [queued]>
[2022-01-05 12:17:42,686] {taskinstance.py:851} INFO - Dependencies all met for <TaskInstance: generate_data.generate_data 2022-01-04T00:00:00+00:00 [queued]>
[2022-01-05 12:17:42,687] {taskinstance.py:1042} INFO - 
--------------------------------------------------------------------------------
[2022-01-05 12:17:42,687] {taskinstance.py:1043} INFO - Starting attempt 1 of 1
[2022-01-05 12:17:42,688] {taskinstance.py:1044} INFO - 
--------------------------------------------------------------------------------
[2022-01-05 12:17:42,747] {taskinstance.py:1063} INFO - Executing <Task(PythonOperator): generate_data> on 2022-01-04T00:00:00+00:00
[2022-01-05 12:17:42,756] {standard_task_runner.py:52} INFO - Started process 44 to run task
[2022-01-05 12:17:42,764] {standard_task_runner.py:76} INFO - Running: ['airflow', 'tasks', 'run', 'generate_data', 'generate_data', '2022-01-04T00:00:00+00:00', '--job-id', '6', '--pool', 'default_pool', '--raw', '--subdir', 'DAGS_FOLDER/geanrate_data.py', '--cfg-path', '/tmp/tmpzlv_9akx', '--error-file', '/tmp/tmph_tig5jo']
[2022-01-05 12:17:42,765] {standard_task_runner.py:77} INFO - Job 6: Subtask generate_data
[2022-01-05 12:17:42,956] {logging_mixin.py:104} INFO - Running <TaskInstance: generate_data.generate_data 2022-01-04T00:00:00+00:00 [running]> on host c2aa36a26221
[2022-01-05 12:17:43,129] {taskinstance.py:1257} INFO - Exporting the following env vars:
AIRFLOW_CTX_DAG_OWNER=airflow
AIRFLOW_CTX_DAG_ID=generate_data
AIRFLOW_CTX_TASK_ID=generate_data
AIRFLOW_CTX_EXECUTION_DATE=2022-01-04T00:00:00+00:00
AIRFLOW_CTX_DAG_RUN_ID=scheduled__2022-01-04T00:00:00+00:00
[2022-01-05 12:17:56,043] {local_task_job.py:146} INFO - Task exited with return code Negsignal.SIGKILL
[2022-01-05 13:26:11,475] {taskinstance.py:851} INFO - Dependencies all met for <TaskInstance: generate_data.generate_data 2022-01-04T00:00:00+00:00 [queued]>
[2022-01-05 13:26:11,523] {taskinstance.py:851} INFO - Dependencies all met for <TaskInstance: generate_data.generate_data 2022-01-04T00:00:00+00:00 [queued]>
[2022-01-05 13:26:11,524] {taskinstance.py:1042} INFO - 
--------------------------------------------------------------------------------
[2022-01-05 13:26:11,525] {taskinstance.py:1043} INFO - Starting attempt 1 of 1
[2022-01-05 13:26:11,525] {taskinstance.py:1044} INFO - 
--------------------------------------------------------------------------------
[2022-01-05 13:26:11,545] {taskinstance.py:1063} INFO - Executing <Task(PythonOperator): generate_data> on 2022-01-04T00:00:00+00:00
[2022-01-05 13:26:11,556] {standard_task_runner.py:52} INFO - Started process 43 to run task
[2022-01-05 13:26:11,580] {standard_task_runner.py:76} INFO - Running: ['airflow', 'tasks', 'run', 'generate_data', 'generate_data', '2022-01-04T00:00:00+00:00', '--job-id', '2', '--pool', 'default_pool', '--raw', '--subdir', 'DAGS_FOLDER/geanrate_data.py', '--cfg-path', '/tmp/tmpq_oe45xg', '--error-file', '/tmp/tmpmxowqip1']
[2022-01-05 13:26:11,582] {standard_task_runner.py:77} INFO - Job 2: Subtask generate_data
[2022-01-05 13:26:11,757] {logging_mixin.py:104} INFO - Running <TaskInstance: generate_data.generate_data 2022-01-04T00:00:00+00:00 [running]> on host 7821c9cd60d1
[2022-01-05 13:26:11,861] {taskinstance.py:1257} INFO - Exporting the following env vars:
AIRFLOW_CTX_DAG_OWNER=airflow
AIRFLOW_CTX_DAG_ID=generate_data
AIRFLOW_CTX_TASK_ID=generate_data
AIRFLOW_CTX_EXECUTION_DATE=2022-01-04T00:00:00+00:00
AIRFLOW_CTX_DAG_RUN_ID=scheduled__2022-01-04T00:00:00+00:00
[2022-01-05 13:26:12,033] {taskinstance.py:1455} ERROR - 'Variable my_iterator does not exist'
Traceback (most recent call last):
  File "/home/airflow/.local/lib/python3.6/site-packages/airflow/models/taskinstance.py", line 1112, in _run_raw_task
    self._prepare_and_execute_task_with_callbacks(context, task)
  File "/home/airflow/.local/lib/python3.6/site-packages/airflow/models/taskinstance.py", line 1285, in _prepare_and_execute_task_with_callbacks
    result = self._execute_task(context, task_copy)
  File "/home/airflow/.local/lib/python3.6/site-packages/airflow/models/taskinstance.py", line 1315, in _execute_task
    result = task_copy.execute(context=context)
  File "/home/airflow/.local/lib/python3.6/site-packages/airflow/operators/python.py", line 117, in execute
    return_value = self.execute_callable()
  File "/home/airflow/.local/lib/python3.6/site-packages/airflow/operators/python.py", line 128, in execute_callable
    return self.python_callable(*self.op_args, **self.op_kwargs)
  File "/opt/airflow/dags/geanrate_data.py", line 21, in generate_data
    n = int(Variable.get('my_iterator'))
  File "/home/airflow/.local/lib/python3.6/site-packages/airflow/models/variable.py", line 128, in get
    raise KeyError(f'Variable {key} does not exist')
KeyError: 'Variable my_iterator does not exist'
[2022-01-05 13:26:12,049] {taskinstance.py:1503} INFO - Marking task as FAILED. dag_id=generate_data, task_id=generate_data, execution_date=20220104T000000, start_date=20220105T132611, end_date=20220105T132612
[2022-01-05 13:26:12,153] {local_task_job.py:146} INFO - Task exited with return code 1
