[2022-01-05 08:55:26,566] {taskinstance.py:851} INFO - Dependencies all met for <TaskInstance: generate_data.generate_data 2022-01-05T08:54:32.387980+00:00 [queued]>
[2022-01-05 08:55:26,634] {taskinstance.py:851} INFO - Dependencies all met for <TaskInstance: generate_data.generate_data 2022-01-05T08:54:32.387980+00:00 [queued]>
[2022-01-05 08:55:26,635] {taskinstance.py:1042} INFO - 
--------------------------------------------------------------------------------
[2022-01-05 08:55:26,636] {taskinstance.py:1043} INFO - Starting attempt 1 of 1
[2022-01-05 08:55:26,636] {taskinstance.py:1044} INFO - 
--------------------------------------------------------------------------------
[2022-01-05 08:55:26,750] {taskinstance.py:1063} INFO - Executing <Task(PythonOperator): generate_data> on 2022-01-05T08:54:32.387980+00:00
[2022-01-05 08:55:26,759] {standard_task_runner.py:52} INFO - Started process 61 to run task
[2022-01-05 08:55:26,769] {standard_task_runner.py:76} INFO - Running: ['airflow', 'tasks', 'run', 'generate_data', 'generate_data', '2022-01-05T08:54:32.387980+00:00', '--job-id', '3', '--pool', 'default_pool', '--raw', '--subdir', 'DAGS_FOLDER/sqldata.py', '--cfg-path', '/tmp/tmpnxyfc4aw', '--error-file', '/tmp/tmpi0c1noxi']
[2022-01-05 08:55:26,770] {standard_task_runner.py:77} INFO - Job 3: Subtask generate_data
[2022-01-05 08:55:26,991] {logging_mixin.py:104} INFO - Running <TaskInstance: generate_data.generate_data 2022-01-05T08:54:32.387980+00:00 [running]> on host e72c695c336a
[2022-01-05 08:55:27,315] {taskinstance.py:1257} INFO - Exporting the following env vars:
AIRFLOW_CTX_DAG_OWNER=airflow
AIRFLOW_CTX_DAG_ID=generate_data
AIRFLOW_CTX_TASK_ID=generate_data
AIRFLOW_CTX_EXECUTION_DATE=2022-01-05T08:54:32.387980+00:00
AIRFLOW_CTX_DAG_RUN_ID=manual__2022-01-05T08:54:32.387980+00:00
[2022-01-05 08:55:32,734] {taskinstance.py:1455} ERROR - [Errno 2] No such file or directory: './data/raw_cdr_data.csv'
Traceback (most recent call last):
  File "/home/airflow/.local/lib/python3.6/site-packages/airflow/models/taskinstance.py", line 1112, in _run_raw_task
    self._prepare_and_execute_task_with_callbacks(context, task)
  File "/home/airflow/.local/lib/python3.6/site-packages/airflow/models/taskinstance.py", line 1285, in _prepare_and_execute_task_with_callbacks
    result = self._execute_task(context, task_copy)
  File "/home/airflow/.local/lib/python3.6/site-packages/airflow/models/taskinstance.py", line 1315, in _execute_task
    result = task_copy.execute(context=context)
  File "/home/airflow/.local/lib/python3.6/site-packages/airflow/operators/python.py", line 117, in execute
    return_value = self.execute_callable()
  File "/home/airflow/.local/lib/python3.6/site-packages/airflow/operators/python.py", line 128, in execute_callable
    return self.python_callable(*self.op_args, **self.op_kwargs)
  File "/opt/airflow/dags/sqldata.py", line 20, in generate_data
    raw_cdr_data = pd.read_csv(dataset_name, header=None, low_memory=False)
  File "/home/airflow/.local/lib/python3.6/site-packages/pandas/io/parsers.py", line 688, in read_csv
    return _read(filepath_or_buffer, kwds)
  File "/home/airflow/.local/lib/python3.6/site-packages/pandas/io/parsers.py", line 454, in _read
    parser = TextFileReader(fp_or_buf, **kwds)
  File "/home/airflow/.local/lib/python3.6/site-packages/pandas/io/parsers.py", line 948, in __init__
    self._make_engine(self.engine)
  File "/home/airflow/.local/lib/python3.6/site-packages/pandas/io/parsers.py", line 1180, in _make_engine
    self._engine = CParserWrapper(self.f, **self.options)
  File "/home/airflow/.local/lib/python3.6/site-packages/pandas/io/parsers.py", line 2010, in __init__
    self._reader = parsers.TextReader(src, **kwds)
  File "pandas/_libs/parsers.pyx", line 382, in pandas._libs.parsers.TextReader.__cinit__
  File "pandas/_libs/parsers.pyx", line 674, in pandas._libs.parsers.TextReader._setup_parser_source
FileNotFoundError: [Errno 2] No such file or directory: './data/raw_cdr_data.csv'
[2022-01-05 08:55:39,103] {taskinstance.py:1503} INFO - Marking task as FAILED. dag_id=generate_data, task_id=generate_data, execution_date=20220105T085432, start_date=20220105T085526, end_date=20220105T085539
[2022-01-05 08:55:46,030] {local_task_job.py:146} INFO - Task exited with return code 1
